Workbook

Sheet Raw_Data
A1: candidate_id | B1: department | C1: role_level | D1: source | E1: recruiter | F1: hiring_manager | G1: location | H1: work_mode | I1: gender | J1: application_date | K1: screening_date | L1: interview_date | M1: offer_date | N1: joining_date | O1: passed_screening | P1: passed_interview | Q1: got_offer | R1: accepted_offer | S1: candidate_dropout | T1: candidate_status | U1: interview_score | V1: time_to_hire_days | W1: experience_years | X1: salary_offered | Y1: offer_rejection_reason
A2: C1001 | B2: Sales | C2: Junior | D2: Naukri | E2: Priya S | F2: Simran Gill | G2: Pune | H2: Onsite | I2: Male | J2: 45222 | K2: 45223 | L2: 45232 | M2: 45238 | N2: 45239 | O2: 1 | P2: 0 | Q2: 0 | R2: 0 | S2: 0 | T2: Interview Rejected | U2: 71 | W2: 0
A3: C1002 | B3: Operations | C3: Analyst | D3: Naukri | E3: Priya S | F3: Kunal Shah | G3: Delhi | H3: Hybrid | I3: Female | J3: 44967 | K3: 44971 | L3: 44981 | M3: 44988 | N3: 44983 | O3: 1 | P3: 1 | Q3: 0 | R3: 0 | S3: 1 | T3: Interview Rejected | U3: 90 | W3: 1
A4: C1003 | B4: Marketing | C4: Analyst | D4: Referral | E4: Priya S | F4: Kunal Shah | G4: Mumbai | H4: Onsite | I4: Male | J4: 45044 | K4: 45046 | L4: 45052 | M4: 45054 | N4: 45070 | O4: 1 | P4: 0 | Q4: 0 | R4: 0 | S4: 0 | T4: Interview Rejected | U4: 48 | W4: 4
A5: C1004 | B5: Sales | C5: Manager | D5: Referral | E5: Priya S | F5: Ravi Verma | G5: Mumbai | H5: Onsite | I5: Female | J5: 45013 | K5: 45017 | L5: 45023 | M5: 45026 | N5: 45034 | O5: 1 | P5: 1 | Q5: 1 | R5: 0 | S5: 1 | T5: Offer Rejected | U5: 64 | W5: 11 | X5: 2535292 | Y5: Role mismatch
A6: C1005 | B6: Sales | C6: Manager | D6: Company Website | E6: Priya S | F6: Kunal Shah | G6: Delhi | H6: Onsite | I6: Female | J6: 45012 | K6: 45017 | L6: 45021 | M6: 45023 | N6: 45036 | O6: 1 | P6: 0 | Q6: 0 | R6: 0 | S6: 0 | T6: Interview Rejected | U6: 58 | W6: 11
A7: C1006 | B7: Marketing | C7: Junior | D7: Naukri | E7: Sneha T | F7: Kunal Shah | G7: Bangalore | H7: Remote | I7: Female | J7: 45320 | K7: 45323 | L7: 45332 | M7: 45338 | N7: 45335 | O7: 1 | P7: 0 | Q7: 0 | R7: 0 | S7: 0 | T7: Interview Rejected | U7: 45 | W7: 1
A8: C1007 | B8: HR | C8: Analyst | D8: LinkedIn | E8: Sneha T | F8: Simran Gill | G8: Hyderabad | H8: Hybrid | I8: Female | J8: 45033 | K8: 45035 | L8: 45040 | M8: 45046 | N8: 45050 | O8: 1 | P8: 1 | Q8: 1 | R8: 1 | S8: 0 | T8: Joined | U8: 59 | V8: 17 | W8: 1 | X8: 739732
A9: C1008 | B9: Marketing | C9: Analyst | D9: Naukri | E9: Rahul M | F9: Neha Kapoor | G9: Hyderabad | H9: Hybrid | I9: Male | J9: 45194 | K9: 45195 | L9: 45200 | M9: 45205 | N9: 45212 | O9: 1 | P9: 0 | Q9: 0 | R9: 0 | S9: 0 | T9: Interview Rejected | U9: 82 | W9: 2
A10: C1009 | B10: Operations | C10: Junior | D10: Naukri | E10: Anita K | F10: Pooja Nair | G10: Pune | H10: Onsite | I10: Female | J10: 45417 | K10: 45418 | L10: 45421 | M10: 45423 | N10: 45431 | O10: 1 | P10: 1 | Q10: 1 | R10: 0 | S10: 0 | T10: Offer Rejected | U10: 53 | W10: 2 | X10: 550299 | Y10: Long hiring process
A11: C1010 | B11: Engineering | C11: Senior | D11: LinkedIn | E11: Sneha T | F11: Kunal Shah | G11: Hyderabad | H11: Remote | I11: Female | J11: 45434 | K11: 45436 | L11: 45446 | M11: 45448 | N11: 45466 | O11: 1 | P11: 1 | Q11: 0 | R11: 0 | S11: 0 | T11: Interview Rejected | U11: 67 | W11: 6
A12: C1011 | B12: Operations | C12: Senior | D12: Campus | E12: Anita K | F12: Ravi Verma | G12: Delhi | H12: Onsite | I12: Male | J12: 45261 | K12: 45264 | L12: 45269 | M12: 45275 | N12: 45288 | O12: 0 | P12: 0 | Q12: 0 | R12: 0 | S12: 1 | T12: Screening Rejected | U12: 82 | W12: 7
A13: C1012 | B13: Marketing | C13: Senior | D13: Campus | E13: Sneha T | F13: Arjun Mehta | G13: Hyderabad | H13: Remote | I13: Female | J13: 45459 | K13: 45464 | L13: 45473 | M13: 45475 | N13: 45478 | O13: 1 | P13: 0 | Q13: 0 | R13: 0 | S13: 0 | T13: Interview Rejected | U13: 48 | W13: 7
A14: C1013 | B14: Sales | C14: Lead | D14: Naukri | E14: Priya S | F14: Arjun Mehta | G14: Delhi | H14: Remote | I14: Male | J14: 44989 | K14: 44990 | L14: 45000 | M14: 45003 | N14: 45004 | O14: 1 | P14: 1 | Q14: 1 | R14: 0 | S14: 0 | T14: Offer Rejected | U14: 73 | W14: 7 | X14: 1747659 | Y14: Long hiring process
A15: C1014 | B15: Engineering | C15: Senior | D15: Company Website | E15: Sneha T | F15: Arjun Mehta | G15: Delhi | H15: Hybrid | I15: Female | J15: 45091 | K15: 45093 | L15: 45098 | M15: 45105 | N15: 45116 | O15: 1 | P15: 1 | Q15: 1 | R15: 0 | S15: 0 | T15: Offer Rejected | U15: 46 | W15: 7 | X15: 1273153 | Y15: Higher salary elsewhere
A16: C1015 | B16: HR | C16: Manager | D16: Referral | E16: Anita K | F16: Kunal Shah | G16: Hyderabad | H16: Hybrid | I16: Female | J16: 45139 | K16: 45142 | L16: 45148 | M16: 45154 | N16: 45151 | O16: 0 | P16: 0 | Q16: 0 | R16: 0 | S16: 1 | T16: Screening Rejected | U16: 62 | W16: 8
A17: C1016 | B17: Sales | C17: Junior | D17: LinkedIn | E17: Anita K | F17: Kunal Shah | G17: Delhi | H17: Onsite | I17: Male | J17: 45176 | K17: 45179 | L17: 45185 | M17: 45188 | N17: 45198 | O17: 0 | P17: 0 | Q17: 0 | R17: 0 | S17: 0 | T17: Screening Rejected | U17: 62 | W17: 0
A18: C1017 | B18: Sales | C18: Manager | D18: LinkedIn | E18: Priya S | F18: Simran Gill | G18: Mumbai | H18: Remote | I18: Male | J18: 45155 | K18: 45158 | L18: 45163 | M18: 45166 | N18: 45167 | O18: 0 | P18: 0 | Q18: 0 | R18: 0 | S18: 0 | T18: Screening Rejected | U18: 82 | W18: 8
A19: C1018 | B19: Sales | C19: Analyst | D19: Naukri | E19: Anita K | F19: Arjun Mehta | G19: Bangalore | H19: Onsite | I19: Female | J19: 45468 | K19: 45471 | L19: 45475 | M19: 45477 | N19: 45492 | O19: 1 | P19: 0 | Q19: 0 | R19: 0 | S19: 0 | T19: Interview Rejected | U19: 59 | W19: 4
A20: C1019 | B20: Sales | C20: Senior | D20: Campus | E20: Priya S | F20: Simran Gill | G20: Bangalore | H20: Remote | I20: Male | J20: 45332 | K20: 45333 | L20: 45340 | M20: 45344 | N20: 45351 | O20: 0 | P20: 0 | Q20: 0 | R20: 0 | S20: 0 | T20: Screening Rejected | U20: 74 | W20: 5
A21: C1020 | B21: Engineering | C21: Analyst | D21: Campus | E21: Anita K | F21: Kunal Shah | G21: Bangalore | H21: Remote | I21: Female | J21: 45089 | K21: 45094 | L21: 45099 | M21: 45105 | N21: 45117 | O21: 1 | P21: 1 | Q21: 1 | R21: 0 | S21: 0 | T21: Offer Rejected | U21: 75 | W21: 3 | X21: 613835 | Y21: Counter offer accepted
A22: C1021 | B22: Marketing | C22: Manager | D22: Referral | E22: Priya S | F22: Kunal Shah | G22: Delhi | H22: Onsite | I22: Female | J22: 45311 | K22: 45312 | L22: 45316 | M22: 45323 | N22: 45339 | O22: 0 | P22: 0 | Q22: 0 | R22: 0 | S22: 0 | T22: Screening Rejected | U22: 62 | W22: 8
A23: C1022 | B23: Finance | C23: Lead | D23: LinkedIn | E23: Sneha T | F23: Kunal Shah | G23: Pune | H23: Remote | I23: Female | J23: 45318 | K23: 45321 | L23: 45324 | M23: 45330 | N23: 45347 | O23: 1 | P23: 1 | Q23: 0 | R23: 0 | S23: 0 | T23: Interview Rejected | U23: 100 | W23: 6
A24: C1023 | B24: Sales | C24: Manager | D24: Company Website | E24: Sneha T | F24: Simran Gill | G24: Bangalore | H24: Hybrid | I24: Male | J24: 45431 | K24: 45432 | L24: 45436 | M24: 45443 | N24: 45444 | O24: 1 | P24: 0 | Q24: 0 | R24: 0 | S24: 0 | T24: Interview Rejected | U24: 46 | W24: 14
A25: C1024 | B25: Marketing | C25: Manager | D25: LinkedIn | E25: Priya S | F25: Ravi Verma | G25: Hyderabad | H25: Hybrid | I25: Female | J25: 45389 | K25: 45391 | L25: 45395 | M25: 45402 | N25: 45413 | O25: 1 | P25: 1 | Q25: 0 | R25: 0 | S25: 1 | T25: Interview Rejected | U25: 80 | W25: 14
A26: C1025 | B26: Sales | C26: Analyst | D26: Referral | E26: Anita K | F26: Pooja Nair | G26: Mumbai | H26: Remote | I26: Female | J26: 45342 | K26: 45346 | L26: 45350 | M26: 45355 | N26: 45356 | O26: 0 | P26: 0 | Q26: 0 | R26: 0 | S26: 0 | T26: Screening Rejected | U26: 77 | W26: 1
A27: C1026 | B27: Engineering | C27: Junior | D27: Referral | E27: Rahul M | F27: Simran Gill | G27: Mumbai | H27: Hybrid | I27: Female | J27: 45273 | K27: 45275 | L27: 45282 | M27: 45286 | N27: 45309 | O27: 1 | P27: 1 | Q27: 1 | R27: 1 | S27: 0 | T27: Joined | U27: 73 | V27: 36 | W27: 2 | X27: 533642
A28: C1027 | B28: Engineering | C28: Manager | D28: Campus | E28: Rahul M | F28: Pooja Nair | G28: Mumbai | H28: Hybrid | I28: Male | J28: 45113 | K28: 45118 | L28: 45123 | M28: 45129 | N28: 45140 | O28: 1 | P28: 0 | Q28: 0 | R28: 0 | S28: 0 | T28: Interview Rejected | U28: 83 | W28: 11
A29: C1028 | B29: Engineering | C29: Manager | D29: Campus | E29: Anita K | F29: Ravi Verma | G29: Delhi | H29: Remote | I29: Male | J29: 45446 | K29: 45447 | L29: 45452 | M29: 45455 | N29: 45477 | O29: 0 | P29: 0 | Q29: 0 | R29: 0 | S29: 0 | T29: Screening Rejected | U29: 55 | W29: 8
A30: C1029 | B30: Sales | C30: Analyst | D30: Referral | E30: Sneha T | F30: Pooja Nair | G30: Pune | H30: Remote | I30: Female | J30: 44944 | K30: 44946 | L30: 44956 | M30: 44958 | N30: 44958 | O30: 0 | P30: 0 | Q30: 0 | R30: 0 | S30: 0 | T30: Screening Rejected | U30: 68 | W30: 1
A31: C1030 | B31: Sales | C31: Lead | D31: Referral | E31: Rahul M | F31: Simran Gill | G31: Delhi | H31: Hybrid | I31: Male | J31: 45243 | K31: 45245 | L31: 45249 | M31: 45256 | N31: 45258 | O31: 1 | P31: 0 | Q31: 0 | R31: 0 | S31: 0 | T31: Interview Rejected | U31: 76 | W31: 6
A32: C1031 | B32: Operations | C32: Analyst | D32: Referral | E32: Sneha T | F32: Simran Gill | G32: Mumbai | H32: Onsite | I32: Female | J32: 45024 | K32: 45026 | L32: 45031 | M32: 45035 | N32: 45053 | O32: 1 | P32: 1 | Q32: 1 | R32: 1 | S32: 0 | T32: Joined | U32: 80 | V32: 29 | W32: 2 | X32: 685814
A33: C1032 | B33: Engineering | C33: Senior | D33: LinkedIn | E33: Anita K | F33: Pooja Nair | G33: Pune | H33: Hybrid | I33: Female | J33: 45122 | K33: 45126 | L33: 45134 | M33: 45137 | N33: 45162 | O33: 1 | P33: 0 | Q33: 0 | R33: 0 | S33: 0 | T33: Interview Rejected | U33: 51 | W33: 3
A34: C1033 | B34: Sales | C34: Junior | D34: Company Website | E34: Deepak R | F34: Arjun Mehta | G34: Mumbai | H34: Onsite | I34: Male | J34: 45377 | K34: 45379 | L34: 45386 | M34: 45391 | N34: 45394 | O34: 1 | P34: 1 | Q34: 0 | R34: 0 | S34: 0 | T34: Interview Rejected | U34: 57 | W34: 2
A35: C1034 | B35: Sales | C35: Senior | D35: Campus | E35: Anita K | F35: Arjun Mehta | G35: Delhi | H35: Hybrid | I35: Male | J35: 45270 | K35: 45274 | L35: 45279 | M35: 45284 | N35: 45285 | O35: 1 | P35: 0 | Q35: 0 | R35: 0 | S35: 1 | T35: Interview Rejected | U35: 76 | W35: 7
A36: C1035 | B36: Marketing | C36: Senior | D36: LinkedIn | E36: Priya S | F36: Neha Kapoor | G36: Delhi | H36: Hybrid | I36: Male | J36: 45293 | K36: 45297 | L36: 45305 | M36: 45310 | N36: 45317 | O36: 1 | P36: 1 | Q36: 0 | R36: 0 | S36: 0 | T36: Interview Rejected | U36: 67 | W36: 7
A37: C1036 | B37: Marketing | C37: Senior | D37: Referral | E37: Deepak R | F37: Arjun Mehta | G37: Delhi | H37: Onsite | I37: Male | J37: 44969 | K37: 44973 | L37: 44979 | M37: 44984 | N37: 44997 | O37: 1 | P37: 0 | Q37: 0 | R37: 0 | S37: 0 | T37: Interview Rejected | U37: 91 | W37: 6
A38: C1037 | B38: Marketing | C38: Senior | D38: Referral | E38: Sneha T | F38: Ravi Verma | G38: Bangalore | H38: Onsite | I38: Female | J38: 45286 | K38: 45288 | L38: 45294 | M38: 45297 | N38: 45301 | O38: 1 | P38: 1 | Q38: 1 | R38: 1 | S38: 0 | T38: Joined | U38: 58 | V38: 15 | W38: 7 | X38: 1144053
A39: C1038 | B39: Finance | C39: Lead | D39: Company Website | E39: Deepak R | F39: Arjun Mehta | G39: Bangalore | H39: Remote | I39: Male | J39: 45268 | K39: 45269 | L39: 45272 | M39: 45276 | N39: 45290 | O39: 1 | P39: 1 | Q39: 1 | R39: 1 | S39: 0 | T39: Joined | U39: 90 | V39: 22 | W39: 8 | X39: 1635814
A40: C1039 | B40: HR | C40: Manager | D40: Campus | E40: Sneha T | F40: Ravi Verma | G40: Hyderabad | H40: Onsite | I40: Male | J40: 44965 | K40: 44967 | L40: 44976 | M40: 44983 | N40: 44980 | O40: 1 | P40: 0 | Q40: 0 | R40: 0 | S40: 1 | T40: Interview Rejected | U40: 46 | W40: 13
...

Sheet Funnel_Summary
A1: Metric | B1: Value
A2: Total Applications | B2: =COUNTA(Raw_Data!A:A)-1 -> 1500
A3: Passed Screening | B3: =SUM(Raw_Data!O:O) -> 1069
A4: Passed Interview | B4: =SUM(Raw_Data!P:P) -> 773
A5: Got Offer | B5: =SUM(Raw_Data!Q:Q) -> 549
A6: Accepted Offer | B6: =SUM(Raw_Data!R:R) -> 260
A7: Screening Rate % | B7: =(B3/B2)*100 -> 71.266667
A8: Interview Rate % | B8: =(B4/B3)*100 -> 72.310571
A9: Offer Rate % | B9: =(B5/B4)*100 -> 71.021992
A10: Acceptance Rate % | B10: =(B6/B5)*100 -> 47.358834

Sheet Department_Analysis
A1: Department | B1: Avg Time To Hire | C1: Hire Count
A2: Engineering | B2: =AVERAGEIFS(Raw_Data!V:V,Raw_Data!B:B,A2,Raw_Data!R:R,1) -> 29.652778 | C2: =COUNTIFS(Raw_Data!B:B,A2,Raw_Data!R:R,1) -> 72
A3: Finance | B3: =AVERAGEIFS(Raw_Data!V:V,Raw_Data!B:B,A3,Raw_Data!R:R,1) -> 25.484848 | C3: =COUNTIFS(Raw_Data!B:B,A3,Raw_Data!R:R,1) -> 33
A4: Operations | B4: =AVERAGEIFS(Raw_Data!V:V,Raw_Data!B:B,A4,Raw_Data!R:R,1) -> 22.346154 | C4: =COUNTIFS(Raw_Data!B:B,A4,Raw_Data!R:R,1) -> 26
A5: Marketing | B5: =AVERAGEIFS(Raw_Data!V:V,Raw_Data!B:B,A5,Raw_Data!R:R,1) -> 22.190476 | C5: =COUNTIFS(Raw_Data!B:B,A5,Raw_Data!R:R,1) -> 42
A6: Sales | B6: =AVERAGEIFS(Raw_Data!V:V,Raw_Data!B:B,A6,Raw_Data!R:R,1) -> 18.984375 | C6: =COUNTIFS(Raw_Data!B:B,A6,Raw_Data!R:R,1) -> 64
A7: HR | B7: =AVERAGEIFS(Raw_Data!V:V,Raw_Data!B:B,A7,Raw_Data!R:R,1) -> 15.913043 | C7: =COUNTIFS(Raw_Data!B:B,A7,Raw_Data!R:R,1) -> 23
A9: Key Finding:
A10: Engineering requires 29.7 days on average to fill a position,
A11: 86.8% longer than HR (15.9 days).
A13: Reducing Engineering hiring cycle to HR benchmark could
A14: save approximately 13.8 days per vacancy and significantly
A15: reduce productivity loss.

Sheet Recruiter_Scorecard
A1: Recruiter | B1: Total Applications | C1: Total Hires | D1: Hire Rate % | E1: Avg Days To Hire | F1: Performance Rating
A2: Priya S | B2: =COUNTIF(Raw_Data!E:E,A2) -> 335 | C2: =COUNTIFS( Raw_Data!E:E,A2, Raw_Data!R:R,1 ) -> 58 | D2: =C2/B2 -> 0.17313433 | E2: =AVERAGEIFS( Raw_Data!V:V, Raw_Data!E:E,A2, Raw_Data!R:R,1 ) -> 23.137931 | F2: =IF(D2>=18%,"High Performer",IF(D2>=17%,"Good","Needs Improvement")) -> Good
A3: Rahul M | B3: =COUNTIF(Raw_Data!E:E,A3) -> 281 | C3: =COUNTIFS( Raw_Data!E:E,A3, Raw_Data!R:R,1 ) -> 48 | D3: =C3/B3 -> 0.17081851 | E3: =AVERAGEIFS( Raw_Data!V:V, Raw_Data!E:E,A3, Raw_Data!R:R,1 ) -> 23.791667 | F3: =IF(D3>=18%,"High Performer",IF(D3>=17%,"Good","Needs Improvement")) -> Good
A4: Anita K | B4: =COUNTIF(Raw_Data!E:E,A4) -> 302 | C4: =COUNTIFS( Raw_Data!E:E,A4, Raw_Data!R:R,1 ) -> 51 | D4: =C4/B4 -> 0.16887417 | E4: =AVERAGEIFS( Raw_Data!V:V, Raw_Data!E:E,A4, Raw_Data!R:R,1 ) -> 23.215686 | F4: =IF(D4>=18%,"High Performer",IF(D4>=17%,"Good","Needs Improvement")) -> Needs Improvement
A5: Deepak R | B5: =COUNTIF(Raw_Data!E:E,A5) -> 252 | C5: =COUNTIFS( Raw_Data!E:E,A5, Raw_Data!R:R,1 ) -> 42 | D5: =C5/B5 -> 0.16666667 | E5: =AVERAGEIFS( Raw_Data!V:V, Raw_Data!E:E,A5, Raw_Data!R:R,1 ) -> 23.690476 | F5: =IF(D5>=18%,"High Performer",IF(D5>=17%,"Good","Needs Improvement")) -> Needs Improvement
A6: Sneha T | B6: =COUNTIF(Raw_Data!E:E,A6) -> 330 | C6: =COUNTIFS( Raw_Data!E:E,A6, Raw_Data!R:R,1 ) -> 61 | D6: =C6/B6 -> 0.18484848 | E6: =AVERAGEIFS( Raw_Data!V:V, Raw_Data!E:E,A6, Raw_Data!R:R,1 ) -> 23.065574 | F6: =IF(D6>=18%,"High Performer",IF(D6>=17%,"Good","Needs Improvement")) -> High Performer
A9: Key Insight:
A10: Sneha T achieved the highest hire rate at 18.5%.
A12: Deepak R recorded the lowest hire rate at 16.7%.
A14: Difference between top and bottom recruiter is only 1.8 percentage points,
A15: Indicating consistent recruiter performance.

Sheet KPI_Dashboard
A1: HR Recruitment KPI Dashboard
L20: Column1 | M20: Column2
L21: KPI | M21: Value
L22: Applications | M22: 1500
L23: Hires | M23: 260
L24: Hire Rate | M24: 0.173
L25: Fastest Dept | M25: HR
L26: Slowest Dept | M26: Engineering
L27: Best Recruiter | M27: Sneha T
